(No info could be read for "-p": geteuid()=2715 but you should be root.)
WARNING:__main__:
*****************************************
Setting OMP_NUM_THREADS environment variable for each process to be 1 in default, to avoid your system being overloaded, please further tune the variable for optimal performance in your application as needed. 
*****************************************
Traceback (most recent call last):
  File "tools/train.py", line 188, in <module>
    main()
  File "tools/train.py", line 125, in main
    cfg.dump(osp.join(cfg.work_dir, osp.basename(args.config)))Traceback (most recent call last):

  File "tools/train.py", line 188, in <module>
  File "/home/kpatel2s/anaconda3/envs/hrfuser-cuda102-torch110-mmcv-full-1317/lib/python3.8/site-packages/mmcv/utils/config.py", line 541, in dump
    main()
  File "tools/train.py", line 125, in main
    cfg.dump(osp.join(cfg.work_dir, osp.basename(args.config)))
  File "/home/kpatel2s/anaconda3/envs/hrfuser-cuda102-torch110-mmcv-full-1317/lib/python3.8/site-packages/mmcv/utils/config.py", line 541, in dump
    f.write(self.pretty_text)
  File "/home/kpatel2s/anaconda3/envs/hrfuser-cuda102-torch110-mmcv-full-1317/lib/python3.8/site-packages/mmcv/utils/config.py", line 496, in pretty_text
    f.write(self.pretty_text)
  File "/home/kpatel2s/anaconda3/envs/hrfuser-cuda102-torch110-mmcv-full-1317/lib/python3.8/site-packages/mmcv/utils/config.py", line 496, in pretty_text
    text, _ = FormatCode(text, style_config=yapf_style, verify=True)
TypeError: FormatCode() got an unexpected keyword argument 'verify'
    text, _ = FormatCode(text, style_config=yapf_style, verify=True)
TypeError: FormatCode() got an unexpected keyword argument 'verify'
Traceback (most recent call last):
  File "tools/train.py", line 188, in <module>
    main()
  File "tools/train.py", line 125, in main
    cfg.dump(osp.join(cfg.work_dir, osp.basename(args.config)))
  File "/home/kpatel2s/anaconda3/envs/hrfuser-cuda102-torch110-mmcv-full-1317/lib/python3.8/site-packages/mmcv/utils/config.py", line 541, in dump
    f.write(self.pretty_text)
  File "/home/kpatel2s/anaconda3/envs/hrfuser-cuda102-torch110-mmcv-full-1317/lib/python3.8/site-packages/mmcv/utils/config.py", line 496, in pretty_text
    text, _ = FormatCode(text, style_config=yapf_style, verify=True)
TypeError: FormatCode() got an unexpected keyword argument 'verify'
Traceback (most recent call last):
  File "tools/train.py", line 188, in <module>
    main()
  File "tools/train.py", line 125, in main
    cfg.dump(osp.join(cfg.work_dir, osp.basename(args.config)))
  File "/home/kpatel2s/anaconda3/envs/hrfuser-cuda102-torch110-mmcv-full-1317/lib/python3.8/site-packages/mmcv/utils/config.py", line 541, in dump
    f.write(self.pretty_text)
  File "/home/kpatel2s/anaconda3/envs/hrfuser-cuda102-torch110-mmcv-full-1317/lib/python3.8/site-packages/mmcv/utils/config.py", line 496, in pretty_text
    text, _ = FormatCode(text, style_config=yapf_style, verify=True)
TypeError: FormatCode() got an unexpected keyword argument 'verify'
ERROR:torch.distributed.elastic.multiprocessing.api:failed (exitcode: 1) local_rank: 0 (pid: 130081) of binary: /home/kpatel2s/anaconda3/envs/hrfuser-cuda102-torch110-mmcv-full-1317/bin/python
Traceback (most recent call last):
  File "/home/kpatel2s/anaconda3/envs/hrfuser-cuda102-torch110-mmcv-full-1317/lib/python3.8/runpy.py", line 194, in _run_module_as_main
    return _run_code(code, main_globals, None,
  File "/home/kpatel2s/anaconda3/envs/hrfuser-cuda102-torch110-mmcv-full-1317/lib/python3.8/runpy.py", line 87, in _run_code
    exec(code, run_globals)
  File "/home/kpatel2s/anaconda3/envs/hrfuser-cuda102-torch110-mmcv-full-1317/lib/python3.8/site-packages/torch/distributed/run.py", line 723, in <module>
    main()
  File "/home/kpatel2s/anaconda3/envs/hrfuser-cuda102-torch110-mmcv-full-1317/lib/python3.8/site-packages/torch/distributed/elastic/multiprocessing/errors/__init__.py", line 345, in wrapper
    return f(*args, **kwargs)
  File "/home/kpatel2s/anaconda3/envs/hrfuser-cuda102-torch110-mmcv-full-1317/lib/python3.8/site-packages/torch/distributed/run.py", line 719, in main
    run(args)
  File "/home/kpatel2s/anaconda3/envs/hrfuser-cuda102-torch110-mmcv-full-1317/lib/python3.8/site-packages/torch/distributed/run.py", line 710, in run
    elastic_launch(
  File "/home/kpatel2s/anaconda3/envs/hrfuser-cuda102-torch110-mmcv-full-1317/lib/python3.8/site-packages/torch/distributed/launcher/api.py", line 131, in __call__
    return launch_agent(self._config, self._entrypoint, list(args))
  File "/home/kpatel2s/anaconda3/envs/hrfuser-cuda102-torch110-mmcv-full-1317/lib/python3.8/site-packages/torch/distributed/launcher/api.py", line 259, in launch_agent
    raise ChildFailedError(
torch.distributed.elastic.multiprocessing.errors.ChildFailedError: 
============================================================
tools/train.py FAILED
------------------------------------------------------------
Failures:
[1]:
  time      : 2023-10-21_23:01:20
  host      : wr15.wr.inf.h-brs.de
  rank      : 1 (local_rank: 1)
  exitcode  : 1 (pid: 130082)
  error_file: <N/A>
  traceback : To enable traceback see: https://pytorch.org/docs/stable/elastic/errors.html
[2]:
  time      : 2023-10-21_23:01:20
  host      : wr15.wr.inf.h-brs.de
  rank      : 2 (local_rank: 2)
  exitcode  : 1 (pid: 130083)
  error_file: <N/A>
  traceback : To enable traceback see: https://pytorch.org/docs/stable/elastic/errors.html
[3]:
  time      : 2023-10-21_23:01:20
  host      : wr15.wr.inf.h-brs.de
  rank      : 3 (local_rank: 3)
  exitcode  : 1 (pid: 130084)
  error_file: <N/A>
  traceback : To enable traceback see: https://pytorch.org/docs/stable/elastic/errors.html
------------------------------------------------------------
Root Cause (first observed failure):
[0]:
  time      : 2023-10-21_23:01:20
  host      : wr15.wr.inf.h-brs.de
  rank      : 0 (local_rank: 0)
  exitcode  : 1 (pid: 130081)
  error_file: <N/A>
  traceback : To enable traceback see: https://pytorch.org/docs/stable/elastic/errors.html
============================================================
