(No info could be read for "-p": geteuid()=2715 but you should be root.)
/home/kpatel2s/anaconda3/envs/hrfuser-cuda102-torch110-mmcv-full-1317/lib/python3.8/site-packages/torch/distributed/launch.py:178: FutureWarning: The module torch.distributed.launch is deprecated
and will be removed in future. Use torchrun.
Note that --use_env is set by default in torchrun.
If your script expects `--local_rank` argument to be set, please
change it to read from `os.environ['LOCAL_RANK']` instead. See 
https://pytorch.org/docs/stable/distributed.html#launch-utility for 
further instructions

  warnings.warn(
WARNING:torch.distributed.run:
*****************************************
Setting OMP_NUM_THREADS environment variable for each process to be 1 in default, to avoid your system being overloaded, please further tune the variable for optimal performance in your application as needed. 
*****************************************
Traceback (most recent call last):
  File "tools/train.py", line 188, in <module>
Traceback (most recent call last):
  File "tools/train.py", line 188, in <module>
    main()
  File "tools/train.py", line 125, in main
Traceback (most recent call last):
  File "tools/train.py", line 188, in <module>
    main()
  File "tools/train.py", line 125, in main
    cfg.dump(osp.join(cfg.work_dir, osp.basename(args.config)))
  File "/home/kpatel2s/anaconda3/envs/hrfuser-cuda102-torch110-mmcv-full-1317/lib/python3.8/site-packages/mmcv/utils/config.py", line 541, in dump
Traceback (most recent call last):
  File "tools/train.py", line 188, in <module>
    cfg.dump(osp.join(cfg.work_dir, osp.basename(args.config)))
  File "/home/kpatel2s/anaconda3/envs/hrfuser-cuda102-torch110-mmcv-full-1317/lib/python3.8/site-packages/mmcv/utils/config.py", line 541, in dump
    main()
  File "tools/train.py", line 125, in main
    main()    
cfg.dump(osp.join(cfg.work_dir, osp.basename(args.config)))
  File "tools/train.py", line 125, in main
  File "/home/kpatel2s/anaconda3/envs/hrfuser-cuda102-torch110-mmcv-full-1317/lib/python3.8/site-packages/mmcv/utils/config.py", line 541, in dump
    cfg.dump(osp.join(cfg.work_dir, osp.basename(args.config)))
  File "/home/kpatel2s/anaconda3/envs/hrfuser-cuda102-torch110-mmcv-full-1317/lib/python3.8/site-packages/mmcv/utils/config.py", line 541, in dump
    f.write(self.pretty_text)
  File "/home/kpatel2s/anaconda3/envs/hrfuser-cuda102-torch110-mmcv-full-1317/lib/python3.8/site-packages/mmcv/utils/config.py", line 496, in pretty_text
    f.write(self.pretty_text)
      File "/home/kpatel2s/anaconda3/envs/hrfuser-cuda102-torch110-mmcv-full-1317/lib/python3.8/site-packages/mmcv/utils/config.py", line 496, in pretty_text
f.write(self.pretty_text)
  File "/home/kpatel2s/anaconda3/envs/hrfuser-cuda102-torch110-mmcv-full-1317/lib/python3.8/site-packages/mmcv/utils/config.py", line 496, in pretty_text
    text, _ = FormatCode(text, style_config=yapf_style, verify=True)
    TypeErrorf.write(self.pretty_text): 
FormatCode() got an unexpected keyword argument 'verify'
  File "/home/kpatel2s/anaconda3/envs/hrfuser-cuda102-torch110-mmcv-full-1317/lib/python3.8/site-packages/mmcv/utils/config.py", line 496, in pretty_text
    text, _ = FormatCode(text, style_config=yapf_style, verify=True)
    TypeErrortext, _ = FormatCode(text, style_config=yapf_style, verify=True): 
FormatCode() got an unexpected keyword argument 'verify'
TypeError: FormatCode() got an unexpected keyword argument 'verify'
    text, _ = FormatCode(text, style_config=yapf_style, verify=True)
TypeError: FormatCode() got an unexpected keyword argument 'verify'
ERROR:torch.distributed.elastic.multiprocessing.api:failed (exitcode: 1) local_rank: 0 (pid: 129182) of binary: /home/kpatel2s/anaconda3/envs/hrfuser-cuda102-torch110-mmcv-full-1317/bin/python
Traceback (most recent call last):
  File "/home/kpatel2s/anaconda3/envs/hrfuser-cuda102-torch110-mmcv-full-1317/lib/python3.8/runpy.py", line 194, in _run_module_as_main
    return _run_code(code, main_globals, None,
  File "/home/kpatel2s/anaconda3/envs/hrfuser-cuda102-torch110-mmcv-full-1317/lib/python3.8/runpy.py", line 87, in _run_code
    exec(code, run_globals)
  File "/home/kpatel2s/anaconda3/envs/hrfuser-cuda102-torch110-mmcv-full-1317/lib/python3.8/site-packages/torch/distributed/launch.py", line 193, in <module>
    main()
  File "/home/kpatel2s/anaconda3/envs/hrfuser-cuda102-torch110-mmcv-full-1317/lib/python3.8/site-packages/torch/distributed/launch.py", line 189, in main
    launch(args)
  File "/home/kpatel2s/anaconda3/envs/hrfuser-cuda102-torch110-mmcv-full-1317/lib/python3.8/site-packages/torch/distributed/launch.py", line 174, in launch
    run(args)
  File "/home/kpatel2s/anaconda3/envs/hrfuser-cuda102-torch110-mmcv-full-1317/lib/python3.8/site-packages/torch/distributed/run.py", line 710, in run
    elastic_launch(
  File "/home/kpatel2s/anaconda3/envs/hrfuser-cuda102-torch110-mmcv-full-1317/lib/python3.8/site-packages/torch/distributed/launcher/api.py", line 131, in __call__
    return launch_agent(self._config, self._entrypoint, list(args))
  File "/home/kpatel2s/anaconda3/envs/hrfuser-cuda102-torch110-mmcv-full-1317/lib/python3.8/site-packages/torch/distributed/launcher/api.py", line 259, in launch_agent
    raise ChildFailedError(
torch.distributed.elastic.multiprocessing.errors.ChildFailedError: 
============================================================
tools/train.py FAILED
------------------------------------------------------------
Failures:
[1]:
  time      : 2023-10-21_22:57:52
  host      : wr15.wr.inf.h-brs.de
  rank      : 1 (local_rank: 1)
  exitcode  : 1 (pid: 129183)
  error_file: <N/A>
  traceback : To enable traceback see: https://pytorch.org/docs/stable/elastic/errors.html
[2]:
  time      : 2023-10-21_22:57:52
  host      : wr15.wr.inf.h-brs.de
  rank      : 2 (local_rank: 2)
  exitcode  : 1 (pid: 129184)
  error_file: <N/A>
  traceback : To enable traceback see: https://pytorch.org/docs/stable/elastic/errors.html
[3]:
  time      : 2023-10-21_22:57:52
  host      : wr15.wr.inf.h-brs.de
  rank      : 3 (local_rank: 3)
  exitcode  : 1 (pid: 129185)
  error_file: <N/A>
  traceback : To enable traceback see: https://pytorch.org/docs/stable/elastic/errors.html
------------------------------------------------------------
Root Cause (first observed failure):
[0]:
  time      : 2023-10-21_22:57:52
  host      : wr15.wr.inf.h-brs.de
  rank      : 0 (local_rank: 0)
  exitcode  : 1 (pid: 129182)
  error_file: <N/A>
  traceback : To enable traceback see: https://pytorch.org/docs/stable/elastic/errors.html
============================================================
