/home/kpatel2s/anaconda3/envs/hrfuser-cuda102-torch110-mmcv-full-1317/lib/python3.8/site-packages/torch/functional.py:445: UserWarning: torch.meshgrid: in an upcoming release, it will be required to pass the indexing argument. (Triggered internally at  ../aten/src/ATen/native/TensorShape.cpp:2157.)
  return _VF.meshgrid(tensors, **kwargs)  # type: ignore[attr-defined]
Traceback (most recent call last):
  File "tools/test.py", line 334, in <module>
    main()
  File "tools/test.py", line 226, in main
    outputs = single_gpu_test(model, data_loader, args.show, args.show_dir,
  File "/home/kpatel2s/kpatel2s/sensor_fusion_rnd/KevinPatelRnD/hrfuser/mmdet/apis/test.py", line 30, in single_gpu_test
    for i, data in enumerate(data_loader):
  File "/home/kpatel2s/anaconda3/envs/hrfuser-cuda102-torch110-mmcv-full-1317/lib/python3.8/site-packages/torch/utils/data/dataloader.py", line 521, in __next__
    data = self._next_data()
  File "/home/kpatel2s/anaconda3/envs/hrfuser-cuda102-torch110-mmcv-full-1317/lib/python3.8/site-packages/torch/utils/data/dataloader.py", line 1203, in _next_data
    return self._process_data(data)
  File "/home/kpatel2s/anaconda3/envs/hrfuser-cuda102-torch110-mmcv-full-1317/lib/python3.8/site-packages/torch/utils/data/dataloader.py", line 1229, in _process_data
    data.reraise()
  File "/home/kpatel2s/anaconda3/envs/hrfuser-cuda102-torch110-mmcv-full-1317/lib/python3.8/site-packages/torch/_utils.py", line 434, in reraise
    raise exception
PermissionError: Caught PermissionError in DataLoader worker process 0.
Original Traceback (most recent call last):
  File "/home/kpatel2s/anaconda3/envs/hrfuser-cuda102-torch110-mmcv-full-1317/lib/python3.8/site-packages/torch/utils/data/_utils/worker.py", line 287, in _worker_loop
    data = fetcher.fetch(index)
  File "/home/kpatel2s/anaconda3/envs/hrfuser-cuda102-torch110-mmcv-full-1317/lib/python3.8/site-packages/torch/utils/data/_utils/fetch.py", line 49, in fetch
    data = [self.dataset[idx] for idx in possibly_batched_index]
  File "/home/kpatel2s/anaconda3/envs/hrfuser-cuda102-torch110-mmcv-full-1317/lib/python3.8/site-packages/torch/utils/data/_utils/fetch.py", line 49, in <listcomp>
    data = [self.dataset[idx] for idx in possibly_batched_index]
  File "/home/kpatel2s/kpatel2s/sensor_fusion_rnd/KevinPatelRnD/hrfuser/mmdet/datasets/custom.py", line 236, in __getitem__
    return self.prepare_test_img(idx)
  File "/home/kpatel2s/kpatel2s/sensor_fusion_rnd/KevinPatelRnD/hrfuser/mmdet/datasets/custom.py", line 287, in prepare_test_img
    return self.pipeline(results)
  File "/home/kpatel2s/kpatel2s/sensor_fusion_rnd/KevinPatelRnD/hrfuser/mmdet/datasets/pipelines/compose.py", line 41, in __call__
    data = t(data)
  File "/home/kpatel2s/kpatel2s/sensor_fusion_rnd/KevinPatelRnD/hrfuser/mmdet/datasets/pipelines/loading.py", line 281, in __call__
    img_bytes = self.file_client.get(name)
  File "/home/kpatel2s/anaconda3/envs/hrfuser-cuda102-torch110-mmcv-full-1317/lib/python3.8/site-packages/mmcv/fileio/file_client.py", line 992, in get
    return self.client.get(filepath)
  File "/home/kpatel2s/anaconda3/envs/hrfuser-cuda102-torch110-mmcv-full-1317/lib/python3.8/site-packages/mmcv/fileio/file_client.py", line 517, in get
    with open(filepath, 'rb') as f:
PermissionError: [Errno 13] Permission denied: 'data/nuscenes/lidar_samples/rih/CAM_FRONT/n008-2018-08-01-16-03-27-0400__CAM_FRONT__1533153857912404.png'

